<?xml version="1.0" ?>
<!-- =================================================================================== -->
<!-- |    This document was autogenerated by xacro from simple_model.urdf.xacro        | -->
<!-- |    EDITING THIS FILE BY HAND IS NOT RECOMMENDED                                 | -->
<!-- =================================================================================== -->
<robot name="simple_model" xmlns:xacro="http://www.ros.org/wiki/xacro">
  <!-- Include materials -->
  <material name="Black">
    <color rgba="0.5 0.0 0.0 1.0"/>
  </material>
  <material name="Red">
    <color rgba="0.8 0.0 0.0 1.0"/>
  </material>
  <material name="White">
    <color rgba="1.0 1.0 1.0 1.0"/>
  </material>
  <link name="world"/>
  <!-- Base link -->
  <link name="base_link">
    <visual>
      <origin rpy="0 0 0" xyz="0 0 0.05"/>
      <geometry>
        <box size="0.1 0.1 0.1"/>
      </geometry>
      <material name="White"/>
    </visual>
    <collision>
      <origin rpy="0 0 0" xyz="0 0 0.05"/>
      <geometry>
        <box size="0.1 0.1 0.1"/>
      </geometry>
    </collision>
    <inertial>
      <mass value="1"/>
      <inertia ixx="1.0" ixy="0.0" ixz="0.0" iyy="0.5" iyz="0.0" izz="1.0"/>
    </inertial>
  </link>
  <gazebo reference="base_link">
    <material>Gazebo/Yellow</material>
  </gazebo>
  <link name="second_link">
    <visual>
      <origin rpy="0 0 0" xyz="0 0 0.1"/>
      <geometry>
        <box size="0.1 0.1 0.2"/>
      </geometry>
    </visual>
    <collision>
      <origin rpy="0 0 0" xyz="0 0 0.1"/>
      <geometry>
        <box size="0.1 0.1 0.2"/>
      </geometry>
    </collision>
    <inertial>
      <mass value="1"/>
      <inertia ixx="1.0" ixy="0.0" ixz="0.0" iyy="0.5" iyz="0.0" izz="1.0"/>
    </inertial>
  </link>
  <gazebo reference="second_link">
    <material>Gazebo/Green</material>
  </gazebo>
  <link name="third_link">
    <visual>
      <origin rpy="0 0 0" xyz="0.1 0 0"/>
      <geometry>
        <box size="0.2 0.1 0.1"/>
      </geometry>
    </visual>
    <collision>
      <origin rpy="0 0 0" xyz="0.1 0 0"/>
      <geometry>
        <box size="0.2 0.1 0.1"/>
      </geometry>
    </collision>
    <inertial>
      <mass value="1"/>
      <inertia ixx="1.0" ixy="0.0" ixz="0.0" iyy="0.5" iyz="0.0" izz="1.0"/>
    </inertial>
  </link>
  <gazebo reference="third_link">
    <material>Gazebo/Blue</material>
  </gazebo>
  <link name="fourth_link">
    <visual>
      <origin rpy="0 0 0" xyz="0.1 0 0"/>
      <geometry>
        <box size="0.2 0.1 0.1"/>
      </geometry>
    </visual>
    <collision>
      <origin rpy="0 0 0" xyz="0.1 0 0"/>
      <geometry>
        <box size="0.2 0.1 0.1"/>
      </geometry>
    </collision>
    <inertial>
      <mass value="1"/>
      <inertia ixx="1.0" ixy="0.0" ixz="0.0" iyy="0.5" iyz="0.0" izz="1.0"/>
    </inertial>
  </link>
  <gazebo reference="fourth_link">
    <material>Gazebo/Pink</material>
  </gazebo>
  <link name="fifth_link">
    <visual>
      <origin rpy="0 0 0" xyz="0.1 0 0"/>
      <geometry>
        <box size="0.2 0.1 0.1"/>
      </geometry>
    </visual>
    <collision>
      <origin rpy="0 0 0" xyz="0.1 0 0"/>
      <geometry>
        <box size="0.2 0.1 0.1"/>
      </geometry>
    </collision>
    <inertial>
      <mass value="1"/>
      <inertia ixx="1.0" ixy="0.0" ixz="0.0" iyy="0.5" iyz="0.0" izz="1.0"/>
    </inertial>
  </link>
  <gazebo reference="fifth_link">
    <material>Gazebo/Black</material>
  </gazebo>
  <link name="sixth_link">
    <visual>
      <origin rpy="0 0 0" xyz="0.1 0 0"/>
      <geometry>
        <box size="0.2 0.1 0.1"/>
      </geometry>
    </visual>
    <collision>
      <origin rpy="0 0 0" xyz="0.1 0 0"/>
      <geometry>
        <box size="0.2 0.1 0.1"/>
      </geometry>
    </collision>
    <inertial>
      <mass value="1"/>
      <inertia ixx="1.0" ixy="0.0" ixz="0.0" iyy="0.5" iyz="0.0" izz="1.0"/>
    </inertial>
  </link>
  <gazebo reference="sixth_link">
    <material>Gazebo/Black</material>
  </gazebo>
  <link name="end_effector">
    <visual>
      <origin rpy="0 0 0" xyz="0 0 0"/>
      <geometry>
        <box size="0.05 0.05 0.05"/>
      </geometry>
    </visual>
    <collision>
      <origin rpy="0 0 0" xyz="0 0 0"/>
      <geometry>
        <box size="0.05 0.05 0.05"/>
      </geometry>
    </collision>
    <inertial>
      <mass value="1"/>
      <inertia ixx="1.0" ixy="0.0" ixz="0.0" iyy="0.5" iyz="0.0" izz="1.0"/>
    </inertial>
  </link>
  <gazebo reference="end_effector">
    <material>Gazebo/Blue</material>
  </gazebo>
  <joint name="fixed" type="fixed">
    <parent link="world"/>
    <child link="base_link"/>
  </joint>
  <joint name="second_joint" type="revolute">
    <origin rpy="0 0 0" xyz="0 0 0.15"/>
    <parent link="base_link"/>
    <child link="second_link"/>
    <axis xyz="0 0 1"/>
    <limit effort="300" lower="0" upper="3.14159" velocity="1"/>
  </joint>
  <joint name="third_joint" type="revolute">
    <origin rpy="0 -1.570795 0" xyz="0 0 0.26"/>
    <parent link="second_link"/>
    <child link="third_link"/>
    <axis xyz="0 0 1"/>
    <limit effort="300" lower="-1.570795" upper="1.570795" velocity="1"/>
  </joint>
  <joint name="fourth_joint" type="revolute">
    <origin rpy="0 0 0" xyz="0.26 0 0"/>
    <parent link="third_link"/>
    <child link="fourth_link"/>
    <axis xyz="0 0 1"/>
    <limit effort="300" lower="-1.570795" upper="1.570795" velocity="1"/>
  </joint>
  <joint name="fifth_joint" type="revolute">
    <origin rpy="0 0 0" xyz="0.26 0 0"/>
    <parent link="fourth_link"/>
    <child link="fifth_link"/>
    <axis xyz="0 0 1"/>
    <limit effort="300" lower="-1.570795" upper="1.570795" velocity="1"/>
  </joint>
  <joint name="sixth_joint" type="revolute">
    <origin rpy="0 0 0" xyz="0.26 0 0"/>
    <parent link="fifth_link"/>
    <child link="sixth_link"/>
    <axis xyz="0 0 1"/>
    <limit effort="300" lower="-1.570795" upper="1.570795" velocity="1"/>
  </joint>
  <joint name="ee_joint" type="fixed">
    <origin rpy="0 0 0" xyz="0.26 0 0"/>
    <parent link="sixth_link"/>
    <child link="end_effector"/>
  </joint>
  <transmission name="tran1">
    <type>transmission_interface/SimpleTransmission</type>
    <joint name="second_joint">
      <hardwareInterface>hardware_interface/PositionJointInterface</hardwareInterface>
    </joint>
    <actuator name="motor1">
      <hardwareInterface>hardware_interface/PositionJointInterface</hardwareInterface>
      <mechanicalReduction>1</mechanicalReduction>
    </actuator>
  </transmission>
  <transmission name="tran1">
    <type>transmission_interface/SimpleTransmission</type>
    <joint name="third_joint">
      <hardwareInterface>hardware_interface/PositionJointInterface</hardwareInterface>
    </joint>
    <actuator name="motor1">
      <hardwareInterface>hardware_interface/PositionJointInterface</hardwareInterface>
      <mechanicalReduction>1</mechanicalReduction>
    </actuator>
  </transmission>
  <transmission name="tran1">
    <type>transmission_interface/SimpleTransmission</type>
    <joint name="fourth_joint">
      <hardwareInterface>hardware_interface/PositionJointInterface</hardwareInterface>
    </joint>
    <actuator name="motor1">
      <hardwareInterface>hardware_interface/PositionJointInterface</hardwareInterface>
      <mechanicalReduction>1</mechanicalReduction>
    </actuator>
  </transmission>
  <transmission name="tran1">
    <type>transmission_interface/SimpleTransmission</type>
    <joint name="fifth_joint">
      <hardwareInterface>hardware_interface/PositionJointInterface</hardwareInterface>
    </joint>
    <actuator name="motor1">
      <hardwareInterface>hardware_interface/PositionJointInterface</hardwareInterface>
      <mechanicalReduction>1</mechanicalReduction>
    </actuator>
  </transmission>
  <transmission name="tran1">
    <type>transmission_interface/SimpleTransmission</type>
    <joint name="sixth_joint">
      <hardwareInterface>hardware_interface/PositionJointInterface</hardwareInterface>
    </joint>
    <actuator name="motor1">
      <hardwareInterface>hardware_interface/PositionJointInterface</hardwareInterface>
      <mechanicalReduction>1</mechanicalReduction>
    </actuator>
  </transmission>
  <gazebo>
    <plugin filename="libgazebo_ros_control.so" name="gazebo_ros_control">
      <robotNamespace>/simple_robotic_model</robotNamespace>
    </plugin>
  </gazebo>
</robot>
